+ model=yangccccc/deepseek-coder-multi
+ dataset=Avatar
+ cache=tmp
+ src=Python
+ tgt=Java
+ python3 translate.py --model yangccccc/deepseek-coder-multi --dataset Avatar --source_lang Python --target_lang Java --cache_dir tmp --use_test
INFO 09-01 18:18:27 [__init__.py:241] Automatically detected platform cuda.
found 250 inputs
INFO 09-01 18:18:29 [utils.py:326] non-default args: {'model': 'yangccccc/deepseek-coder-multi', 'trust_remote_code': True, 'dtype': 'bfloat16', 'max_model_len': 4096, 'tensor_parallel_size': 2, 'disable_log_stats': True}
The argument `trust_remote_code` is to be used with Auto classes. It has no effect here and is ignored.
INFO 09-01 18:18:37 [__init__.py:711] Resolved architecture: LlamaForCausalLM
`torch_dtype` is deprecated! Use `dtype` instead!
INFO 09-01 18:18:37 [__init__.py:1750] Using max model len 4096
INFO 09-01 18:18:38 [scheduler.py:222] Chunked prefill is enabled with max_num_batched_tokens=8192.
[1;36m(EngineCore_0 pid=1232843)[0;0m INFO 09-01 18:18:38 [core.py:636] Waiting for init message from front-end.
[1;36m(EngineCore_0 pid=1232843)[0;0m INFO 09-01 18:18:38 [core.py:74] Initializing a V1 LLM engine (v0.10.1.1) with config: model='yangccccc/deepseek-coder-multi', speculative_config=None, tokenizer='yangccccc/deepseek-coder-multi', skip_tokenizer_init=False, tokenizer_mode=auto, revision=None, override_neuron_config={}, tokenizer_revision=None, trust_remote_code=True, dtype=torch.bfloat16, max_seq_len=4096, download_dir=None, load_format=auto, tensor_parallel_size=2, pipeline_parallel_size=1, disable_custom_all_reduce=False, quantization=None, enforce_eager=False, kv_cache_dtype=auto, device_config=cuda, decoding_config=DecodingConfig(backend='auto', disable_fallback=False, disable_any_whitespace=False, disable_additional_properties=False, reasoning_backend=''), observability_config=ObservabilityConfig(show_hidden_metrics_for_version=None, otlp_traces_endpoint=None, collect_detailed_traces=None), seed=0, served_model_name=yangccccc/deepseek-coder-multi, enable_prefix_caching=True, chunked_prefill_enabled=True, use_async_output_proc=True, pooler_config=None, compilation_config={"level":3,"debug_dump_path":"","cache_dir":"","backend":"","custom_ops":[],"splitting_ops":["vllm.unified_attention","vllm.unified_attention_with_output","vllm.mamba_mixer2"],"use_inductor":true,"compile_sizes":[],"inductor_compile_config":{"enable_auto_functionalized_v2":false},"inductor_passes":{},"cudagraph_mode":1,"use_cudagraph":true,"cudagraph_num_of_warmups":1,"cudagraph_capture_sizes":[512,504,496,488,480,472,464,456,448,440,432,424,416,408,400,392,384,376,368,360,352,344,336,328,320,312,304,296,288,280,272,264,256,248,240,232,224,216,208,200,192,184,176,168,160,152,144,136,128,120,112,104,96,88,80,72,64,56,48,40,32,24,16,8,4,2,1],"cudagraph_copy_inputs":false,"full_cuda_graph":false,"pass_config":{},"max_capture_size":512,"local_cache_dir":null}
[1;36m(EngineCore_0 pid=1232843)[0;0m WARNING 09-01 18:18:38 [multiproc_worker_utils.py:273] Reducing Torch parallelism from 240 threads to 1 to avoid unnecessary CPU contention. Set OMP_NUM_THREADS in the external environment to tune this value as needed.
[1;36m(EngineCore_0 pid=1232843)[0;0m INFO 09-01 18:18:38 [shm_broadcast.py:289] vLLM message queue communication handle: Handle(local_reader_ranks=[0, 1], buffer_handle=(2, 16777216, 10, 'psm_74e35ae3'), local_subscribe_addr='ipc:///tmp/766c3707-9090-402f-a7d2-e627a39db4d1', remote_subscribe_addr=None, remote_addr_ipv6=False)
[1;36m(EngineCore_0 pid=1232843)[0;0m [1;36m(VllmWorker TP1 pid=1232851)[0;0m INFO 09-01 18:18:41 [shm_broadcast.py:289] vLLM message queue communication handle: Handle(local_reader_ranks=[0], buffer_handle=(1, 10485760, 10, 'psm_1bffe9a7'), local_subscribe_addr='ipc:///tmp/7fbe23a2-586c-4233-a02d-84f2884ad5cb', remote_subscribe_addr=None, remote_addr_ipv6=False)
[1;36m(EngineCore_0 pid=1232843)[0;0m [1;36m(VllmWorker TP0 pid=1232849)[0;0m INFO 09-01 18:18:41 [shm_broadcast.py:289] vLLM message queue communication handle: Handle(local_reader_ranks=[0], buffer_handle=(1, 10485760, 10, 'psm_a07d6e6e'), local_subscribe_addr='ipc:///tmp/4c652c10-dc44-495c-83c5-6ecbab2e5c80', remote_subscribe_addr=None, remote_addr_ipv6=False)
[1;36m(EngineCore_0 pid=1232843)[0;0m [1;36m(VllmWorker TP1 pid=1232851)[0;0m ERROR 09-01 18:18:41 [multiproc_executor.py:559] WorkerProc failed to start.
[1;36m(EngineCore_0 pid=1232843)[0;0m [1;36m(VllmWorker TP1 pid=1232851)[0;0m ERROR 09-01 18:18:41 [multiproc_executor.py:559] Traceback (most recent call last):
[1;36m(EngineCore_0 pid=1232843)[0;0m [1;36m(VllmWorker TP1 pid=1232851)[0;0m ERROR 09-01 18:18:41 [multiproc_executor.py:559]   File "/home/ubuntu/GeneBenchCode/venv/lib/python3.10/site-packages/vllm/v1/executor/multiproc_executor.py", line 533, in worker_main
[1;36m(EngineCore_0 pid=1232843)[0;0m [1;36m(VllmWorker TP1 pid=1232851)[0;0m ERROR 09-01 18:18:41 [multiproc_executor.py:559]     worker = WorkerProc(*args, **kwargs)
[1;36m(EngineCore_0 pid=1232843)[0;0m [1;36m(VllmWorker TP1 pid=1232851)[0;0m ERROR 09-01 18:18:41 [multiproc_executor.py:559]   File "/home/ubuntu/GeneBenchCode/venv/lib/python3.10/site-packages/vllm/v1/executor/multiproc_executor.py", line 401, in __init__
[1;36m(EngineCore_0 pid=1232843)[0;0m [1;36m(VllmWorker TP1 pid=1232851)[0;0m ERROR 09-01 18:18:41 [multiproc_executor.py:559]     self.worker.init_device()
[1;36m(EngineCore_0 pid=1232843)[0;0m [1;36m(VllmWorker TP1 pid=1232851)[0;0m ERROR 09-01 18:18:41 [multiproc_executor.py:559]   File "/home/ubuntu/GeneBenchCode/venv/lib/python3.10/site-packages/vllm/worker/worker_base.py", line 603, in init_device
[1;36m(EngineCore_0 pid=1232843)[0;0m [1;36m(VllmWorker TP1 pid=1232851)[0;0m ERROR 09-01 18:18:41 [multiproc_executor.py:559]     self.worker.init_device()  # type: ignore
[1;36m(EngineCore_0 pid=1232843)[0;0m [1;36m(VllmWorker TP1 pid=1232851)[0;0m ERROR 09-01 18:18:41 [multiproc_executor.py:559]   File "/home/ubuntu/GeneBenchCode/venv/lib/python3.10/site-packages/vllm/v1/worker/gpu_worker.py", line 179, in init_device
[1;36m(EngineCore_0 pid=1232843)[0;0m [1;36m(VllmWorker TP1 pid=1232851)[0;0m ERROR 09-01 18:18:41 [multiproc_executor.py:559]     raise ValueError(
[1;36m(EngineCore_0 pid=1232843)[0;0m [1;36m(VllmWorker TP1 pid=1232851)[0;0m ERROR 09-01 18:18:41 [multiproc_executor.py:559] ValueError: Free memory on device (65.17/79.15 GiB) on startup is less than desired GPU memory utilization (0.9, 71.24 GiB). Decrease GPU memory utilization or reduce GPU memory used by other processes.
[1;36m(EngineCore_0 pid=1232843)[0;0m ERROR 09-01 18:18:42 [core.py:700] EngineCore failed to start.
[1;36m(EngineCore_0 pid=1232843)[0;0m ERROR 09-01 18:18:42 [core.py:700] Traceback (most recent call last):
[1;36m(EngineCore_0 pid=1232843)[0;0m ERROR 09-01 18:18:42 [core.py:700]   File "/home/ubuntu/GeneBenchCode/venv/lib/python3.10/site-packages/vllm/v1/engine/core.py", line 691, in run_engine_core
[1;36m(EngineCore_0 pid=1232843)[0;0m ERROR 09-01 18:18:42 [core.py:700]     engine_core = EngineCoreProc(*args, **kwargs)
[1;36m(EngineCore_0 pid=1232843)[0;0m ERROR 09-01 18:18:42 [core.py:700]   File "/home/ubuntu/GeneBenchCode/venv/lib/python3.10/site-packages/vllm/v1/engine/core.py", line 492, in __init__
[1;36m(EngineCore_0 pid=1232843)[0;0m ERROR 09-01 18:18:42 [core.py:700]     super().__init__(vllm_config, executor_class, log_stats,
[1;36m(EngineCore_0 pid=1232843)[0;0m ERROR 09-01 18:18:42 [core.py:700]   File "/home/ubuntu/GeneBenchCode/venv/lib/python3.10/site-packages/vllm/v1/engine/core.py", line 80, in __init__
[1;36m(EngineCore_0 pid=1232843)[0;0m ERROR 09-01 18:18:42 [core.py:700]     self.model_executor = executor_class(vllm_config)
[1;36m(EngineCore_0 pid=1232843)[0;0m ERROR 09-01 18:18:42 [core.py:700]   File "/home/ubuntu/GeneBenchCode/venv/lib/python3.10/site-packages/vllm/executor/executor_base.py", line 54, in __init__
[1;36m(EngineCore_0 pid=1232843)[0;0m ERROR 09-01 18:18:42 [core.py:700]     self._init_executor()
[1;36m(EngineCore_0 pid=1232843)[0;0m ERROR 09-01 18:18:42 [core.py:700]   File "/home/ubuntu/GeneBenchCode/venv/lib/python3.10/site-packages/vllm/v1/executor/multiproc_executor.py", line 96, in _init_executor
[1;36m(EngineCore_0 pid=1232843)[0;0m ERROR 09-01 18:18:42 [core.py:700]     self.workers = WorkerProc.wait_for_ready(unready_workers)
[1;36m(EngineCore_0 pid=1232843)[0;0m ERROR 09-01 18:18:42 [core.py:700]   File "/home/ubuntu/GeneBenchCode/venv/lib/python3.10/site-packages/vllm/v1/executor/multiproc_executor.py", line 472, in wait_for_ready
[1;36m(EngineCore_0 pid=1232843)[0;0m ERROR 09-01 18:18:42 [core.py:700]     raise e from None
[1;36m(EngineCore_0 pid=1232843)[0;0m ERROR 09-01 18:18:42 [core.py:700] Exception: WorkerProc initialization failed due to an exception in a background process. See stack trace for root cause.
[1;36m(EngineCore_0 pid=1232843)[0;0m Process EngineCore_0:
[1;36m(EngineCore_0 pid=1232843)[0;0m Traceback (most recent call last):
[1;36m(EngineCore_0 pid=1232843)[0;0m   File "/usr/lib/python3.10/multiprocessing/process.py", line 314, in _bootstrap
[1;36m(EngineCore_0 pid=1232843)[0;0m     self.run()
[1;36m(EngineCore_0 pid=1232843)[0;0m   File "/usr/lib/python3.10/multiprocessing/process.py", line 108, in run
[1;36m(EngineCore_0 pid=1232843)[0;0m     self._target(*self._args, **self._kwargs)
[1;36m(EngineCore_0 pid=1232843)[0;0m   File "/home/ubuntu/GeneBenchCode/venv/lib/python3.10/site-packages/vllm/v1/engine/core.py", line 704, in run_engine_core
[1;36m(EngineCore_0 pid=1232843)[0;0m     raise e
[1;36m(EngineCore_0 pid=1232843)[0;0m   File "/home/ubuntu/GeneBenchCode/venv/lib/python3.10/site-packages/vllm/v1/engine/core.py", line 691, in run_engine_core
[1;36m(EngineCore_0 pid=1232843)[0;0m     engine_core = EngineCoreProc(*args, **kwargs)
[1;36m(EngineCore_0 pid=1232843)[0;0m   File "/home/ubuntu/GeneBenchCode/venv/lib/python3.10/site-packages/vllm/v1/engine/core.py", line 492, in __init__
[1;36m(EngineCore_0 pid=1232843)[0;0m     super().__init__(vllm_config, executor_class, log_stats,
[1;36m(EngineCore_0 pid=1232843)[0;0m   File "/home/ubuntu/GeneBenchCode/venv/lib/python3.10/site-packages/vllm/v1/engine/core.py", line 80, in __init__
[1;36m(EngineCore_0 pid=1232843)[0;0m     self.model_executor = executor_class(vllm_config)
[1;36m(EngineCore_0 pid=1232843)[0;0m   File "/home/ubuntu/GeneBenchCode/venv/lib/python3.10/site-packages/vllm/executor/executor_base.py", line 54, in __init__
[1;36m(EngineCore_0 pid=1232843)[0;0m     self._init_executor()
[1;36m(EngineCore_0 pid=1232843)[0;0m   File "/home/ubuntu/GeneBenchCode/venv/lib/python3.10/site-packages/vllm/v1/executor/multiproc_executor.py", line 96, in _init_executor
[1;36m(EngineCore_0 pid=1232843)[0;0m     self.workers = WorkerProc.wait_for_ready(unready_workers)
[1;36m(EngineCore_0 pid=1232843)[0;0m   File "/home/ubuntu/GeneBenchCode/venv/lib/python3.10/site-packages/vllm/v1/executor/multiproc_executor.py", line 472, in wait_for_ready
[1;36m(EngineCore_0 pid=1232843)[0;0m     raise e from None
[1;36m(EngineCore_0 pid=1232843)[0;0m Exception: WorkerProc initialization failed due to an exception in a background process. See stack trace for root cause.
/usr/lib/python3.10/multiprocessing/resource_tracker.py:224: UserWarning: resource_tracker: There appear to be 1 leaked shared_memory objects to clean up at shutdown
  warnings.warn('resource_tracker: There appear to be %d '
Traceback (most recent call last):
  File "/home/ubuntu/translation/scripts/translate.py", line 272, in <module>
    main(args)
  File "/home/ubuntu/translation/scripts/translate.py", line 77, in main
    vllm_model = LLM(
  File "/home/ubuntu/GeneBenchCode/venv/lib/python3.10/site-packages/vllm/entrypoints/llm.py", line 285, in __init__
    self.llm_engine = LLMEngine.from_engine_args(
  File "/home/ubuntu/GeneBenchCode/venv/lib/python3.10/site-packages/vllm/engine/llm_engine.py", line 490, in from_engine_args
    return engine_cls.from_vllm_config(
  File "/home/ubuntu/GeneBenchCode/venv/lib/python3.10/site-packages/vllm/v1/engine/llm_engine.py", line 127, in from_vllm_config
    return cls(vllm_config=vllm_config,
  File "/home/ubuntu/GeneBenchCode/venv/lib/python3.10/site-packages/vllm/v1/engine/llm_engine.py", line 104, in __init__
    self.engine_core = EngineCoreClient.make_client(
  File "/home/ubuntu/GeneBenchCode/venv/lib/python3.10/site-packages/vllm/v1/engine/core_client.py", line 80, in make_client
    return SyncMPClient(vllm_config, executor_class, log_stats)
  File "/home/ubuntu/GeneBenchCode/venv/lib/python3.10/site-packages/vllm/v1/engine/core_client.py", line 600, in __init__
    super().__init__(
  File "/home/ubuntu/GeneBenchCode/venv/lib/python3.10/site-packages/vllm/v1/engine/core_client.py", line 446, in __init__
    with launch_core_engines(vllm_config, executor_class,
  File "/usr/lib/python3.10/contextlib.py", line 142, in __exit__
    next(self.gen)
  File "/home/ubuntu/GeneBenchCode/venv/lib/python3.10/site-packages/vllm/v1/engine/utils.py", line 706, in launch_core_engines
    wait_for_engine_startup(
  File "/home/ubuntu/GeneBenchCode/venv/lib/python3.10/site-packages/vllm/v1/engine/utils.py", line 759, in wait_for_engine_startup
    raise RuntimeError("Engine core initialization failed. "
RuntimeError: Engine core initialization failed. See root cause above. Failed core proc(s): {'EngineCore_0': 1}
+ python3 clean_generations_translation.py --model yangccccc/deepseek-coder-multi --dataset Avatar --source_lang Python --target_lang Java --remove_prompt --use_test
Traceback (most recent call last):
  File "/home/ubuntu/translation/scripts/clean_generations_translation.py", line 49, in <module>
    for solution_path in tqdm(load_solutions(folder_path, EXTENSIONS[args.target_lang])):
  File "/home/ubuntu/translation/scripts/clean_generations_translation.py", line 7, in load_solutions
    files = os.listdir(samples_dir)
FileNotFoundError: [Errno 2] No such file or directory: '../Experiment_Results/intermediate/SR/Translation/use_test/deepseek-coder-multi/Avatar/Python/Java'
+ python3 -u test_translation.py --dataset Avatar --source_lang Python --target_lang Java --model yangccccc/deepseek-coder-multi --test_type use_test
testing translations
../Experiment_Results/intermediate/SR/Translation/use_test/deepseek-coder-multi/Avatar/Python/Java-sanitized/pass_id.txt
#Success: 0
Success: []
Fail: []
